Workbook

Sheet Tracciati
A1: id | B1: ref | C1: lettera | D1: region | E1: gruppo | F1: from | G1: to | H1: distance | I1: ascent | J1: descent
A2: 30221 | B2: SI Z01 | C2: Z | D2: Sardegna | E2: 1-Isole | F2: Chiesa del Buon Cammino | G2: Saltàra | H2: 8.38 | I2: 172 | J2: 127
A3: 29164 | B3: SI Z02 | C3: Z | D3: Sardegna | E3: 1-Isole | F3: Saltàra | G3: Luogosanto | H3: 24.29 | I3: 686 | J3: 470
A4: 29446 | B4: SI Z03 | C4: Z | D4: Sardegna | E4: 1-Isole | F4: Luogosanto | G4: Sant'Antonio di Gallura | H4: 24.05 | I4: 786 | J4: 766
A5: 30231 | B5: SI Z04 | C5: Z | D5: Sardegna | E5: 1-Isole | F5: Sant'Antonio di Gallura | G5: Calangianus | H5: 24.07 | I5: 751 | J5: 567
A6: 29221 | B6: SI Z05 | C6: Z | D6: Sardegna | E6: 1-Isole | F6: Calangianus | G6: Monti | H6: 34.79 | I6: 1006 | J6: 1225
A7: 30247 | B7: SI Z06 | C7: Z | D7: Sardegna | E7: 1-Isole | F7: Monti | G7: Caserma Forestale Bolostiu | H7: 15.59 | I7: 713 | J7: 390
A8: 29704 | B8: SI Z07 | C8: Z | D8: Sardegna | E8: 1-Isole | F8: Caserma Forestale Bolostiu | G8: Alà dei Sardi | H8: 17.97 | I8: 765 | J8: 726
A9: 29613 | B9: SI Z08 | C9: Z | D9: Sardegna | E9: 1-Isole | F9: Alà dei Sardi | G9: Caserma Juanne Stuppa | H9: 20.49 | I9: 543 | J9: 905
A10: 29750 | B10: SI Z09 | C10: Z | D10: Sardegna | E10: 1-Isole | F10: Caserma forestale "Gianni Stuppa" | G10: Vecchia Cantoniera di Sant'Anna | H10: 26.15 | I10: 1661 | J10: 1333
A11: 29208 | B11: SI Z10A | C11: Z | D11: Sardegna | E11: 1-Isole | F11: Vecchia Cantoniera di Sant’Anna | G11: Norghio | H11: 33.57 | I11: 1567 | J11: 1651
A12: 29354 | B12: SI Z10B | C12: Z | D12: Sardegna | E12: 1-Isole | F12: Norghio | G12: Galtelli | H12: 22.31 | I12: 413 | J12: 1028
A13: 29705 | B13: SI Z11 | C13: Z | D13: Sardegna | E13: 1-Isole | F13: Galtelli | G13: Orosei | H13: 13.05 | I13: 969 | J13: 983
... A101: 1158 | B101: SI U33 | C101: U | D101: Calabria | E101: 2-Calabria | F101: Morano Calabro | G101: Bivacco Gaudolino | H101: 11.9 | I101: 1100 | J101: 50
A102: 29973 | B102: SI T01 | C102: T | D102: Basilicata | E102: 3-Sud | F102: Bivacco Gaudolino | G102: Madonna di Pollino | I102: 1498 | J102: 618
A103: 29740 | B103: SI T02 | C103: T | D103: Basilicata | E103: 3-Sud | F103: Madonna di Pollino | G103: San Severino Lucano | H103: 20.14 | I103: 567 | J103: 1194
A104: 29175 | B104: SI T03 | C104: T | D104: Basilicata | E104: 3-Sud | F104: San Severino Lucano | G104: Latronico | H104: 27.94 | I104: 1042 | J104: 1097
A105: 29169 | B105: SI T04 | C105: T | D105: Basilicata | E105: 3-Sud | F105: Latronico | G105: Castelsaraceno | H105: 15 | I105: 1095 | J105: 987
A106: 29678 | B106: SI T05 | C106: T | D106: Basilicata | E106: 3-Sud | F106: Castelsaraceno | G106: Conserva Lauria | H106: 27.46 | I106: 1316 | J106: 848
A107: 29681 | B107: SI T06 | C107: T | D107: Basilicata | E107: 3-Sud | F107: Conserva Lauria | G107: Lago Sirino | H107: 15.12 | I107: 706 | J107: 1343
A108: 29183 | B108: SI T07 | C108: T | D108: Basilicata | E108: 3-Sud | F108: Lago Sirino | G108: Rivello | H108: 15.1 | I108: 401 | J108: 727
A109: 29171 | B109: SI T08 | C109: T | D109: Basilicata | E109: 3-Sud | F109: Rivello | G109: Fortino | H109: 22.46 | I109: 1186 | J109: 870
A110: 29757 | B110: SI S01 | C110: S | D110: Campania | E110: 3-Sud | F110: Fortino | G110: Sanza | H110: 21.71 | I110: 945 | J110: 1163
A111: 29124 | B111: SI S02 | C111: S | D111: Campania | E111: 3-Sud | F111: Sanza | G111: Rifugio Cervati | H111: 10.35 | I111: 1185 | J111: 119
A112: 29916 | B112: SI S03 | C112: S | D112: Campania | E112: 3-Sud | F112: Rifugio Cervati | G112: Piaggine | H112: 16.01 | I112: 348 | J112: 1353
A113: 29212 | B113: SI S04 | C113: S | D113: Campania | E113: 3-Sud | F113: Piaggine | G113: Casone Aresta | H113: 33.6 | I113: 1898 | J113: 1368
A114: 29719 | B114: SI S05 | C114: S | D114: Campania | E114: 3-Sud | F114: Casone Aresta | G114: Sicignano degli Alburni | H114: 14.27 | I114: 743 | J114: 1274
... A179: 29215 | B179: SI Q11 | C179: Q | D179: Molise | E179: 3-Sud | F179: Carovilli | G179: San Pietro Avellana | H179: 15.41 | I179: 460 | J179: 348
A180: 29189 | B180: SI Q12 | C180: Q | D180: Molise | E180: 3-Sud | F180: San Pietro Avellana | G180: Rivisondoli | I180: 724 | J180: 424
A181: 29975 | B181: SI P01 | C181: P | D181: Abruzzo | E181: 4-Centro | F181: Pescasseroli | G181: Alvito - Loc. Trichiano | H181: 11.17 | I181: 526 | J181: 772
A182: 29744 | B182: SI P02 | C182: P | D182: Abruzzo | E182: 4-Centro | F182: Barrea | G182: Pescasseroli | H182: 26.35 | I182: 1036 | J182: 935
A183: 29745 | B183: SI P03 | C183: P | D183: Abruzzo | E183: 4-Centro | F183: Rivisondoli | G183: Barrea | H183: 21.89 | I183: 857 | J183: 1147
A184: 29199 | B184: SI P04 | C184: P | D184: Abruzzo | E184: 4-Centro | F184: Rivisondoli | G184: Campo di Giove | H184: 22.19 | I184: 1117 | J184: 1367
A185: 29219 | B185: SI P05 | C185: P | D185: Abruzzo | E185: 4-Centro | F185: Campo di Giove | G185: Rocacaramanico | H185: 18.88 | I185: 1019 | J185: 864
A186: 29954 | B186: SI P06 | C186: P | D186: Abruzzo | E186: 4-Centro | F186: Rocacaramanico | G186: Jaccio Grande | H186: 10.73 | I186: 993 | J186: 323
A187: 29698 | B187: SI P07 | C187: P | D187: Abruzzo | E187: 4-Centro | F187: Jaccio Grande | G187: Popoli | H187: 17.08 | I187: 345 | J187: 1801
A188: 29606 | B188: SI P08 | C188: P | D188: Abruzzo | E188: 4-Centro | F188: Popoli | G188: Ofena | H188: 22.02 | I188: 561 | J188: 315
A189: 29937 | B189: SI P09 | C189: P | D189: Abruzzo | E189: 4-Centro | F189: Ofena | G189: Santo Stefano di Sessanio | H189: 19.2 | I189: 1073 | J189: 343
A190: 29751 | B190: SI P10 | C190: P | D190: Abruzzo | E190: 4-Centro | F190: Santo Stefano di Sessanio | G190: Rifugio Duca degli Abruzzi | H190: 18.58 | I190: 1505 | J190: 354
A191: 29741 | B191: SI P11 | C191: P | D191: Abruzzo | E191: 4-Centro | F191: Rifugio Duca degli Abruzzi | G191: Pietracamela | H191: 12.96 | I191: 183 | J191: 1533
...

Sheet Riepilogo per Regione
A1: Lettera | B1: Regione | C1: # | D1: Gruppo | F1: Gruppi | G1: # | H1: FORMATO | I1: Lettere | J1: Regioni | L1: lettera | M1: region | N1: gruppo | O1: num_tappe | P1: formato | R1: A4 MAX | S1: =7*12
A2: Z | B2: Sardegna | C2: =COUNTIF(Tracciati!$C$2:$C$536,A2) | D2: 1-Isole | F2: {=UNIQUE(D2:D19)} | G2: =SUMIF($D$2:$D$19,F2,$C$2:$C$19) | H2: A4 | I2: Z,V | L2: Z | M2: Sardegna | N2: Isole | O2: 30 | P2: A4 | R2: A5 MAX | S2: =12*3
A3: V | B3: Sicilia | C3: =COUNTIF(Tracciati!$C$2:$C$536,A3) | D3: 1-Isole | F3: 2-Calabria | G3: =SUMIF($D$2:$D$19,F3,$C$2:$C$19) | H3: A5 | I3: U | L3: V | M3: Sicilia | N3: Isole | O3: 37 | P3: A4
A4: U | B4: Calabria | C4: =COUNTIF(Tracciati!$C$2:$C$536,A4) | D4: 2-Calabria | F4: 3-Sud | G4: =SUMIF($D$2:$D$19,F4,$C$2:$C$19) | H4: A4 | I4: Q,R,S,T | L4: U | M4: Calabria | N4: Sud | O4: 33 | P4: A4
A5: T | B5: Basilicata | C5: =COUNTIF(Tracciati!$C$2:$C$536,A5) | D5: 3-Sud | F5: 4-Centro | G5: =SUMIF($D$2:$D$19,F5,$C$2:$C$19) | H5: A4 | I5: N,O,P | L5: T | M5: Basilicata | N5: Sud | O5: 12 | P5: A4
A6: S | B6: Campania | C6: =COUNTIF(Tracciati!$C$2:$C$536,A6) | D6: 3-Sud | F6: 5-Centro Nord | G6: =SUMIF($D$2:$D$19,F6,$C$2:$C$19) | H6: A4 | I6: L,G | L6: S | M6: Campania | N6: Sud | O6: 30 | P6: A4
A7: R | B7: Puglia | C7: =COUNTIF(Tracciati!$C$2:$C$536,A7) | D7: 3-Sud | F7: 6-Piemonte | G7: =SUMIF($D$2:$D$19,F7,$C$2:$C$19) | H7: A4 | I7: E | L7: R | M7: Puglia | N7: Centro Sud | O7: 25 | P7: A4
A8: Q | B8: Molise | C8: =COUNTIF(Tracciati!$C$2:$C$536,A8) | D8: 3-Sud | F8: 7-Valle d'Aosta | G8: =SUMIF($D$2:$D$19,F8,$C$2:$C$19) | H8: A5 | I8: F | L8: Q | M8: Molise | N8: Centro Sud | O8: 12 | P8: A4
A9: P | B9: Abruzzo | C9: =COUNTIF(Tracciati!$C$2:$C$536,A9) | D9: 4-Centro | F9: 8-Lombardia | G9: =SUMIF($D$2:$D$19,F9,$C$2:$C$19) | H9: A4 | I9: D | L9: P | M9: Abruzzo | N9: Centro Sud | O9: 18 | P9: A4
A10: O | B10: Lazio | C10: =COUNTIF(Tracciati!$C$2:$C$536,A10) | D10: 4-Centro | F10: 9-Nord Est | G10: =SUMIF($D$2:$D$19,F10,$C$2:$C$19) | H10: A4 | I10: A,B,C | L10: O | M10: Lazio | N10: Centro Sud | O10: 20 | P10: A4
A11: N | B11: Marche / Umbria | C11: =COUNTIF(Tracciati!$C$2:$C$536,A11) | D11: 4-Centro | L11: N | M11: Marche | N11: Centro Sud | O11: 9 | P11: A4
A12: L | B12: Toscana / Emilia-Romagna | C12: =COUNTIF(Tracciati!$C$2:$C$536,A12) | D12: 5-Centro Nord | L12: L | M12: Toscana/Emilia Romagna | N12: Centro Nord | O12: 34 | P12: A4
A13: G | B13: Liguria | C13: =COUNTIF(Tracciati!$C$2:$C$536,A13) | D13: 5-Centro Nord | L13: G | M13: Liguria | N13: Centro Nord | O13: 35 | P13: A4
A14: E | B14: Piemonte | C14: =COUNTIF(Tracciati!$C$2:$C$536,A14) | D14: 6-Piemonte | L14: E | M14: Piemonte | N14: Piemonte | O14: 83 | P14: A4
A15: F | B15: Valle d'Aosta | C15: =COUNTIF(Tracciati!$C$2:$C$536,A15) | D15: 7-Valle d'Aosta | L15: F | M15: Valle d'Aosta | N15: Valle d'Aosta | O15: 20 | P15: A5
A16: D | B16: Lombardia | C16: =COUNTIF(Tracciati!$C$2:$C$536,A16) | D16: 8-Lombardia | L16: D | M16: Lombardia | N16: Lombardia | O16: 60 | P16: A4
A17: B | B17: Veneto | C17: =COUNTIF(Tracciati!$C$2:$C$536,A17) | D17: 9-Nord Est | L17: B | M17: Veneto | N17: Nord Est | O17: 9 | P17: A4
A18: C | B18: Trentino - Alto Adige | C18: =COUNTIF(Tracciati!$C$2:$C$536,A18) | D18: 9-Nord Est | L18: C | M18: Trentino-Alto Adige | N18: Nord Est | O18: 30 | P18: A4
A19: A | B19: Friuli Venezia Giulia | C19: =COUNTIF(Tracciati!$C$2:$C$536,A19) | D19: 9-Nord Est | L19: A | M19: Friuli Venezia Giulia | N19: Nord Est | O19: 29 | P19: A4
C21: =SUM(C2:C19)

Sheet Riepilogo per Gruppo
A1: lettera | B1: gruppo | C1: num_totale | D1: formato
A2: Z/V | B2: 1-Isole | C2: 67 | D2: A4
A3: U | B3: 2-Calabria | C3: 33 | D3: A5
A4: T/S/R/Q | B4: 3-Sud | C4: 79 | D4: A4
A5: P/O/N | B5: 4-Centro | C5: 56 | D5: A4
A6: L/G | B6: 5-Centro Nord | C6: 69 | D6: A4
A7: E | B7: 6-Piemonte | C7: 83 | D7: A4
A8: F | B8: 7-Valle d'Aosta | C8: 20 | D8: A5
A9: D | B9: 8-Lombardia | C9: 60 | D9: A4
A10: B/C/A | B10: 9-Nord Est | C10: 68 | D10: A4

Sheet Isole
A1: ordine | B1: region | C1: ref | D1: from | E1: to | F1: gruppo
A2: 1 | B2: Sardegna | C2: SI Z01 | D2: Chiesa del Buon Cammino | E2: Saltàra | F2: 1-Isole
A3: 2 | B3: Sardegna | C3: SI Z02 | D3: Saltàra | E3: Luogosanto | F3: 1-Isole
A4: 3 | B4: Sardegna | C4: SI Z03 | D4: Luogosanto | E4: Sant'Antonio di Gallura | F4: 1-Isole
A5: 4 | B5: Sardegna | C5: SI Z04 | D5: Sant'Antonio di Gallura | E5: Calangianus | F5: 1-Isole
A6: 5 | B6: Sardegna | C6: SI Z05 | D6: Calangianus | E6: Monti | F6: 1-Isole
A7: 6 | B7: Sardegna | C7: SI Z06 | D7: Monti | E7: Caserma Forestale Bolostiu | F7: 1-Isole
A8: 7 | B8: Sardegna | C8: SI Z07 | D8: Caserma Forestale Bolostiu | E8: Alà dei Sardi | F8: 1-Isole
A9: 8 | B9: Sardegna | C9: SI Z08 | D9: Alà dei Sardi | E9: Caserma Juanne Stuppa | F9: 1-Isole
A10: 9 | B10: Sardegna | C10: SI Z09 | D10: Caserma forestale "Gianni Stuppa" | E10: Vecchia Cantoniera di Sant'Anna | F10: 1-Isole
A11: 10 | B11: Sardegna | C11: SI Z10A | D11: Vecchia Cantoniera di Sant’Anna | E11: Norghio | F11: 1-Isole
A12: 11 | B12: Sardegna | C12: SI Z10B | D12: Norghio | E12: Galtelli | F12: 1-Isole
A13: 12 | B13: Sardegna | C13: SI Z11 | D13: Galtelli | E13: Orosei | F13: 1-Isole
... A68: 67 | B68: Sicilia | C68: SI V29 | D68: Portella Armacera | E68: Messina | F68: 1-Isole

Sheet Calabria
A1: ordine | B1: region | C1: ref | D1: from | E1: to | F1: gruppo
A2: 1 | B2: Calabria | C2: SI U01 | D2: Reggio Calabria | E2: Gambarie | F2: 2-Calabria
A3: 2 | B3: Calabria | C3: SI U02 | D3: Gambarie | E3: Polsi | F3: 2-Calabria
A4: 3 | B4: Calabria | C4: SI U03 | D4: Polsi | E4: San Luca | F4: 2-Calabria
A5: 4 | B5: Calabria | C5: SI U04 | D5: San Luca | E5: Piani di Zervò | F5: 2-Calabria
A6: 5 | B6: Calabria | C6: SI U05 | D6: Piani di Zervò | E6: Trepitò | F6: 2-Calabria
A7: 6 | B7: Calabria | C7: SI U06 | D7: Trepitò | E7: Passo del Mercante | F7: 2-Calabria
A8: 7 | B8: Calabria | C8: SI U07 | D8: Passo del Mercante | E8: Limina | F8: 2-Calabria
A9: 8 | B9: Calabria | C9: SI U08 | D9: Limina | E9: Mongiana | F9: 2-Calabria
A10: 9 | B10: Calabria | C10: SI U09 | D10: Mongiana | E10: Serra San Bruno | F10: 2-Calabria
A11: 10 | B11: Calabria | C11: SI U10 | D11: Serra San Bruno | E11: Torre di Ruggiero | F11: 2-Calabria
A12: 11 | B12: Calabria | C12: SI U11 | D12: Torre di Ruggiero | E12: San Vito Sullo Ionio | F12: 2-Calabria
A13: 12 | B13: Calabria | C13: SI U12 | D13: San Vito sullo Ionio | E13: Girifalco | F13: 2-Calabria
... A34: 33 | B34: Calabria | C34: SI U33 | D34: Morano Calabro | E34: Bivacco Gaudolino | F34: 2-Calabria

Sheet Sud
A1: ordine | B1: region | C1: ref | D1: from | E1: to | F1: gruppo
A2: 1 | B2: Basilicata | C2: SI T01 | D2: Bivacco Gaudolino | E2: Madonna di Pollino | F2: 3-Sud
A3: 2 | B3: Basilicata | C3: SI T02 | D3: Madonna di Pollino | E3: San Severino Lucano | F3: 3-Sud
A4: 3 | B4: Basilicata | C4: SI T03 | D4: San Severino Lucano | E4: Latronico | F4: 3-Sud
A5: 4 | B5: Basilicata | C5: SI T04 | D5: Latronico | E5: Castelsaraceno | F5: 3-Sud
A6: 5 | B6: Basilicata | C6: SI T05 | D6: Castelsaraceno | E6: Conserva Lauria | F6: 3-Sud
A7: 6 | B7: Basilicata | C7: SI T06 | D7: Conserva Lauria | E7: Lago Sirino | F7: 3-Sud
A8: 7 | B8: Basilicata | C8: SI T07 | D8: Lago Sirino | E8: Rivello | F8: 3-Sud
A9: 8 | B9: Basilicata | C9: SI T08 | D9: Rivello | E9: Fortino | F9: 3-Sud
A10: 9 | B10: Campania | C10: SI S01 | D10: Fortino | E10: Sanza | F10: 3-Sud
A11: 10 | B11: Campania | C11: SI S02 | D11: Sanza | E11: Rifugio Cervati | F11: 3-Sud
A12: 11 | B12: Campania | C12: SI S03 | D12: Rifugio Cervati | E12: Piaggine | F12: 3-Sud
A13: 12 | B13: Campania | C13: SI S04 | D13: Piaggine | E13: Casone Aresta | F13: 3-Sud
... A80: 79 | B80: Molise | C80: SI Q12 | D80: San Pietro Avellana | E80: Rivisondoli | F80: 3-Sud

Sheet Centro
A1: ordine | B1: region | C1: ref | D1: from | E1: to | F1: gruppo
A2: 1 | B2: Abruzzo | C2: SI P01 | D2: Pescasseroli | E2: Alvito - Loc. Trichiano | F2: 4-Centro
A3: 2 | B3: Abruzzo | C3: SI P02 | D3: Barrea | E3: Pescasseroli | F3: 4-Centro
A4: 3 | B4: Abruzzo | C4: SI P03 | D4: Rivisondoli | E4: Barrea | F4: 4-Centro
A5: 4 | B5: Abruzzo | C5: SI P04 | D5: Rivisondoli | E5: Campo di Giove | F5: 4-Centro
A6: 5 | B6: Abruzzo | C6: SI P05 | D6: Campo di Giove | E6: Rocacaramanico | F6: 4-Centro
A7: 6 | B7: Abruzzo | C7: SI P06 | D7: Rocacaramanico | E7: Jaccio Grande | F7: 4-Centro
A8: 7 | B8: Abruzzo | C8: SI P07 | D8: Jaccio Grande | E8: Popoli | F8: 4-Centro
A9: 8 | B9: Abruzzo | C9: SI P08 | D9: Popoli | E9: Ofena | F9: 4-Centro
A10: 9 | B10: Abruzzo | C10: SI P09 | D10: Ofena | E10: Santo Stefano di Sessanio | F10: 4-Centro
A11: 10 | B11: Abruzzo | C11: SI P10 | D11: Santo Stefano di Sessanio | E11: Rifugio Duca degli Abruzzi | F11: 4-Centro
A12: 11 | B12: Abruzzo | C12: SI P11 | D12: Rifugio Duca degli Abruzzi | E12: Pietracamela | F12: 4-Centro
A13: 12 | B13: Abruzzo | C13: SI P12 | D13: Pietracamela | E13: Nerito | F13: 4-Centro
... A57: 56 | B57: Marche / Umbria | C57: SI N18 | D57: Bocca Serriola | E57: Bocca Trabaria | F57: 4-Centro

Sheet Centro Nord
A1: ordine | B1: region | C1: ref | D1: from | E1: to | F1: gruppo
A2: 1 | B2: Toscana / Emilia-Romagna | C2: SI L01 | D2: Bocca Trabaria | E2: Passo di Viamaggio | F2: 5-Centro Nord
A3: 2 | B3: Toscana / Emilia-Romagna | C3: SI L02N | D3: Passo di Viamaggio | E3: Balze | F3: 5-Centro Nord
A4: 3 | B4: Toscana / Emilia-Romagna | C4: SI L03N | D4: Balze | E4: Verghereto | F4: 5-Centro Nord
A5: 4 | B5: Toscana / Emilia-Romagna | C5: SI L04N | D5: Verghereto | E5: Badia Prataglia | F5: 5-Centro Nord
A6: 5 | B6: Toscana / Emilia-Romagna | C6: SI L02S | D6: Passo di Viamaggio | E6: Caprese Michelangelo | F6: 5-Centro Nord
A7: 6 | B7: Toscana / Emilia-Romagna | C7: SI L03S | D7: Caprese Michelangelo | E7: Chiusi della Verna | F7: 5-Centro Nord
A8: 7 | B8: Toscana / Emilia-Romagna | C8: SI L04S | D8: Chiusi della Verna | E8: Rotta dei Cavalli - innesto con L04N fino a Badia Prataglia | F8: 5-Centro Nord
A9: 8 | B9: Toscana / Emilia-Romagna | C9: SI L05 | D9: Badia Prataglia | E9: Passo della Calla | F9: 5-Centro Nord
A10: 9 | B10: Toscana / Emilia-Romagna | C10: SI L06 | D10: Passo La Calla | E10: Passo del Muraglione | F10: 5-Centro Nord
A11: 10 | B11: Toscana / Emilia-Romagna | C11: SI L07 | D11: Passo del Muraglione | E11: Passo della Colla di Casaglia | F11: 5-Centro Nord
A12: 11 | B12: Toscana / Emilia-Romagna | C12: SI L08 | D12: Passo della Colla di Casaglia | E12: Passo del Giogo di Scarperia | F12: 5-Centro Nord
A13: 12 | B13: Toscana / Emilia-Romagna | C13: SI L09 | D13: Passo del Giogo di Scarperia | E13: Passo della Futa | F13: 5-Centro Nord
... A70: 69 | B70: Liguria | C70: SI G34 | D70: Sella della Valletta | E70: Tetti delle Donzelle | F70: 5-Centro Nord

Sheet Piemonte
A1: ordine | B1: region | C1: ref | D1: from | E1: to | F1: gruppo
A2: 1 | B2: Piemonte | C2: SI E01 | D2: Garessio | E2: Ormea | F2: 6-Piemonte
A3: 2 | B3: Piemonte | C3: SI E02 | D3: Ormea | E3: Rifugio Mongioie | F3: 6-Piemonte
A4: 3 | B4: Piemonte | C4: SI E03 | D4: Rifugio Mongioie | E4: Rifugio Havis De Giorgio - Mondovì alla Sella del Piscio | F4: 6-Piemonte
A5: 4 | B5: Piemonte | C5: SI E04 | D5: Rifugio Havis de Giorgio | E5: Rifugio Garelli | F5: 6-Piemonte
A6: 5 | B6: Piemonte | C6: SI E05 | D6: Rifugio Garelli | E6: Limonetto | F6: 6-Piemonte
A7: 6 | B7: Piemonte | C7: SI E06 | D7: Limonetto | E7: Palanfrè | F7: 6-Piemonte
A8: 7 | B8: Piemonte | C8: SI E07 | D8: Pallanfrè | E8: Trinità | F8: 6-Piemonte
A9: 8 | B9: Piemonte | C9: SI E08 | D9: Trinità | E9: Rifugio Soria-Ellena | F9: 6-Piemonte
A10: 9 | B10: Piemonte | C10: SI E09 | D10: Rifugio Soria-Ellena | E10: Rifugio Genova- Figari | F10: 6-Piemonte
A11: 10 | B11: Piemonte | C11: SI E10 | D11: Rifugio Genova-Figari | E11: Terme di Valdieri | F11: 6-Piemonte
A12: 11 | B12: Piemonte | C12: SI E11 | D12: Terme di Valdieri | E12: Rifugio Citta' di Ceva al Malinvern | F12: 6-Piemonte
A13: 12 | B13: Piemonte | C13: SI E12 | D13: Rifugio Citta' di Ceva al Malinvern | E13: Sant'Anna di Vinadio | F13: 6-Piemonte
... A84: 83 | B84: Piemonte | C84: SI E69 | D84: Falmenta | E84: Cannobio | F84: 6-Piemonte

Sheet Valle d'Aosta
A1: ordine | B1: region | C1: ref | D1: from | E1: to | F1: gruppo
A2: 1 | B2: Valle d'Aosta | C2: SI F01 | D2: Rifugio Savoia | E2: Rhemes-Notre-Dame | F2: 7-Valle d'Aosta
A3: 2 | B3: Valle d'Aosta | C3: SI F02 | D3: Rhemes-Notre-Dame | E3: Rifugio Chalet de l'Epèè | F3: 7-Valle d'Aosta
A4: 3 | B4: Valle d'Aosta | C4: SI F03 | D4: Rifugio Chalet de l'Epèè | E4: Planaval | F4: 7-Valle d'Aosta
A5: 4 | B5: Valle d'Aosta | C5: SI F04 | D5: Planaval | E5: Rifugio Deffeyes | F5: 7-Valle d'Aosta
A6: 5 | B6: Valle d'Aosta | C6: SI F05 | D6: Rifugio Deffeyes | E6: La Thuile | F6: 7-Valle d'Aosta
A7: 6 | B7: Valle d'Aosta | C7: SI F06 | D7: La Thuile | E7: Rifugio Elisabetta | F7: 7-Valle d'Aosta
A8: 7 | B8: Valle d'Aosta | C8: SI F07 | D8: Rifugio Elisabetta | E8: Courmayeur | F8: 7-Valle d'Aosta
A9: 8 | B9: Valle d'Aosta | C9: SI F08 | D9: Courmayeur | E9: Rifugio Bonatti | F9: 7-Valle d'Aosta
A10: 9 | B10: Valle d'Aosta | C10: SI F09 | D10: Rifugio Bonatti | E10: Rifugio Frassati | F10: 7-Valle d'Aosta
A11: 10 | B11: Valle d'Aosta | C11: SI F10 | D11: Rifugio Frassati | E11: Saint-Rhemy | F11: 7-Valle d'Aosta
A12: 11 | B12: Valle d'Aosta | C12: SI F11 | D12: Saint-Rhemy | E12: Rifugio Champillon | F12: 7-Valle d'Aosta
A13: 12 | B13: Valle d'Aosta | C13: SI F12 | D13: Rifugio Champillon | E13: Rey | F13: 7-Valle d'Aosta
... A21: 20 | B21: Valle d'Aosta | C21: SI F20 | D21: Gressoney-Saint-Jean | E21: Ponte Napoleonico - Valvogna | F21: 7-Valle d'Aosta

Sheet Lombardia
A1: ordine | B1: region | C1: ref | D1: from | E1: to | F1: gruppo
A2: 1 | B2: Lombardia | C2: SI D01 | D2: Cannobio - Luino | E2: Lago Delio | F2: 8-Lombardia
A3: 2 | B3: Lombardia | C3: SI D02 | D3: Lago Delio | E3: Monteviasco | F3: 8-Lombardia
A4: 3 | B4: Lombardia | C4: SI D03 | D4: Monteviasco | E4: Rifugio Campiglio al Pradecolo | F4: 8-Lombardia
A5: 4 | B5: Lombardia | C5: SI D04 | D5: Rifugio Campiglio al Pradecolo | E5: Diga di Creva (Luino) | F5: 8-Lombardia
A6: 5 | B6: Lombardia | C6: SI D05 | D6: Diga di Creva (Luino) | E6: Marchirolo | F6: 8-Lombardia
A7: 6 | B7: Lombardia | C7: SI D06 | D7: Marchirolo | E7: Porto Ceresio | F7: 8-Lombardia
A8: 7 | B8: Lombardia | C8: SI D07 | D8: Porto Ceresio | E8: Viggiù - Piazza Europa | F8: 8-Lombardia
A9: 8 | B9: Lombardia | C9: SI D08 | D9: Viggiù - Piazza Europa | E9: Bizzarone | F9: 8-Lombardia
A10: 9 | B10: Lombardia | C10: SI D09 | D10: Bizzarone | E10: Como | F10: 8-Lombardia
A11: 10 | B11: Lombardia | C11: SI D10N | D11: Como - Villa Olmo | E11: Rifugio Prabello | F11: 8-Lombardia
A12: 11 | B12: Lombardia | C12: SI D11N | D12: Rifugio Prabello | E12: Rifugio Boffalora | F12: 8-Lombardia
A13: 12 | B13: Lombardia | C13: SI D12N | D13: Rifugio Boffalora | E13: Grandola e Uniti (Frazione Cardano) | F13: 8-Lombardia
... A61: 60 | B61: Lombardia | C61: SI D30S | D61: Temù | E61: Rifugio Angelino Bozzi al Montozzo | F61: 8-Lombardia

Sheet Nord Est
A1: ordine | B1: region | C1: ref | D1: from | E1: to | F1: gruppo
A2: 1 | B2: Veneto | C2: SI B01 | D2: Rifugio Marmolada Pian di Fedaia | E2: Arabba | F2: 9-Nord Est
A3: 2 | B3: Veneto | C3: SI B02 | D3: Arabba | E3: Pralongià | F3: 9-Nord Est
A4: 3 | B4: Veneto | C4: SI B03 | D4: Pralongià | E4: Rifugio Lagazuoi | F4: 9-Nord Est
A5: 4 | B5: Veneto | C5: SI B04 | D5: Rifugio Lagazuoi | E5: Albergo Rifugio Ospitale | F5: 9-Nord Est
A6: 5 | B6: Veneto | C6: SI B05 | D6: Albergo Rifugio Ospitale | E6: Misurina | F6: 9-Nord Est
A7: 6 | B7: Veneto | C7: SI B06 | D7: Misurina | E7: Rifugio Locatelli alle Tre Cime di Lavaredo (Dreizinnenhutte) | F7: 9-Nord Est
A8: 7 | B8: Veneto | C8: SI B07 | D8: Rifugio Locatelli alle Tre Cime di Lavaredo (Dreizinnenhutte) | E8: Rifugio Casera Rinfredo | F8: 9-Nord Est
A9: 8 | B9: Veneto | C9: SI B08 | D9: Rifugio Casera Rinfredo | E9: Casera Dignas | F9: 9-Nord Est
A10: 9 | B10: Veneto | C10: SI B09 | D10: Casera Dignas | E10: Bivio Rifugio Calvi | F10: 9-Nord Est
A11: 10 | B11: Trentino - Alto Adige | C11: SI C01 | D11: Rifugio Bozzi | E11: Pejo | F11: 9-Nord Est
A12: 11 | B12: Trentino - Alto Adige | C12: SI C02 | D12: Peio | E12: Bagni di Rabbi | F12: 9-Nord Est
A13: 12 | B13: Trentino - Alto Adige | C13: SI C03 | D13: Bagni di Rabbi | E13: Malga Bordolona di Sotto | F13: 9-Nord Est
... A69: 68 | B69: Friuli Venezia Giulia | C69: SI A28 | D69: Muggia | E69: San Bartolomeo | F69: 9-Nord Est
